# 예외처리가 필요한 이유

- 자바에서의 예외처리는 "프로그램의 비정상적인 종료를 막고, 상태를 정상상태로 유지하기 위함입니다."
- 예외를 처리하는 문법은 try-catch 문, try-catch-finally 문이 있습니다.

```
try {


} catch(Exception e){


}
```
- try-catch에서 예외가 발생하지 않을 경우 try 블록에 있는 모든 문장이 수행되어지고, try-catch문 이후의 문장이 수행되어집니다.
- try-catch에서 예외가 발생한 경우
  - try 블록 내에서 예외가 발생한 부분 이후의 문장들은 실행되지 않습니다.
  - catch 블록에 있는 모든 문장이 수행되어지고 try-catch 이후의 문장이 수행되어집니다.
    
 
```
// 예외가 발생하지 않은 경우
public class ExceptionVariable {

    public static void main(String[] args) {
        ExceptionVariable sample = new ExceptionVariable();
        sample.checkVariable();
    }

    private void checkVariable() {
        int[] intArr = new int[5];
        try{
            System.out.println(intArr[5]);
        }catch (Exception e){
            System.out.println(intArr.length);
        }
        System.out.println("finshCode");
    }
}


```

```
// 예외가 발생한 경우
public class ExceptionVariable2 {

    public static void main(String[] args) {
        ExceptionVariable2 sample = new ExceptionVariable2();
        sample.checkVariable();
    }

    private void checkVariable() {
        int[] intArr = new int[5];
        try{
            System.out.println("try 블럭 수행");
            System.out.println(intArr[6]);
        }catch (Exception e){
            System.out.println("catch 블럭 수행");
            System.out.println(intArr.length);
            System.out.println(e.getMessage());
        }
        System.out.println("블록 이후의 문장이 수행되어집니다.");
    }
}


```
또한 try 블록과 catch 블록은 분리되어져 있어서 변수의 선언을 주의해야한다.


```
=

public class ExceptionVariable3 {

    public static void main(String[] args) {
        ExceptionVariable3 sample = new ExceptionVariable3();
        sample.checkVariable();
    }

    private void checkVariable() {

        try{
            int[] intArr = new int[5];
            System.out.println("try 블럭 수행");
            System.out.println(intArr[6]);
        }catch (Exception e){
            System.out.println("catch 블럭 수행");
            System.out.println(intArr.length); // 변수를 찾을 수 없어서 에러발생. cannot find symbol
            System.out.println(e.getMessage());
        }
        System.out.println("블록 이후의 문장이 수행되어집니다.");
    }
}
```

그래서 아래와 같이 try 블럭 앞에 변수를 미리 선언해 놓는다.

```
package exception;

public class ExceptionVariable4 {

    public static void main(String[] args) {
        ExceptionVariable3 sample = new ExceptionVariable3();
        sample.checkVariable();
    }

    private void checkVariable() {
        int[] intArr = null; // 변수를 미리 선언합니다.
        try{
            intArr = new int[5];
            System.out.println("try 블럭 수행");
            System.out.println(intArr[6]);
        }catch (Exception e){
            System.out.println("catch 블럭 수행");
            System.out.println(intArr.length);
            System.out.println(e.getMessage());
        }
        System.out.println("블록 이후의 문장이 수행되어집니다.");
    }
}

```

try-catch-finally

- try-catch문에 추가적으로 붙을 수 있는 finally라는 블록이 있습니다.
- 예외 발생 여부와 관계없이 반드시 실행되어지는 블럭입니다.

```
public class FinallySample {

    public static void main(String[] args) {
        FinallySample sample = new FinallySample();
        sample.finallySample();
    }

    private void finallySample() {

        int[] intArr = null;
        try{
            intArr = new int[5];
            System.out.println("try 블럭 수행");
            System.out.println(intArr[5]); // 예외발생
        }catch (Exception e){
            System.out.println("catch 블럭 수행");
            System.out.println(intArr.length);
            System.out.println(e.getMessage());
        }finally {
            System.out.println("반드시 실행되어지는 finally 블록입니다.");
        }
        System.out.println("블록 이후의 문장이 수행되어집니다.");

    }
// 예외가 발생하지 않아도 finally 구문은 동작한다.
     private void finallySample() {

        int[] intArr = null;
        try{
            intArr = new int[5];
            System.out.println("try 블럭 수행");
            System.out.println(intArr[4]); 
        }catch (Exception e){
            System.out.println("catch 블럭 수행");
            System.out.println(intArr.length);
            System.out.println(e.getMessage());
        }finally {
            System.out.println("반드시 실행되어지는 finally 블록입니다.");
        }
        System.out.println("블록 이후의 문장이 수행되어집니다.");

    }

}

// 결과
try 블럭 수행
catch 블럭 수행
5
Index 5 out of bounds for length 5
반드시 실행되어지는 finally 블록입니다.
블록 이후의 문장이 수행되어집니다.


```

catch 블록은 여러개 사용할 수 있습니다.

```
public class MutiCatch {

    public static void main(String[] args) {
        MutiCatch sample = new MutiCatch();
        sample.finallySample();
    }

    private void finallySample() {

        int[] intArr = null;
        try {
            intArr = new int[5];
            System.out.println("try 블럭 수행");
            System.out.println(intArr[8]);
        } catch (ArrayIndexOutOfBoundsException ex) {
            System.out.println("첫 번째 catch 블럭 수행하기");
            System.out.println(ex.getMessage());
        } catch (Exception e) {
            System.out.println("catch 블럭 수행");
             System.out.println(e.getMessage());
        }
        System.out.println("블록 이후의 문장이 수행되어집니다.");

    }
}

```

catch 블럭의 순서는 매우 중요합니다. catch 블럭의 순서대로 예외를 처리를 진행합니다.

```
public class MutiCatch2 {

    public static void main(String[] args) {
        MutiCatch sample = new MutiCatch();
        sample.finallySample();
    }

    private void finallySample() {

        int[] intArr = null;
        try {
            intArr = new int[5];
            System.out.println("try 블럭 수행");
            System.out.println(intArr[8]);
        }catch (NullPointerException ex2){
            System.out.println("NullPointerException catch 블럭 수행하기");
            ex2.getMessage();
        } catch (ArrayIndexOutOfBoundsException ex) {
            System.out.println("ArrayIndexOutOfBoundsException catch 블럭 수행하기");
            System.out.println(ex.getMessage());
        } catch (Exception e) {
            System.out.println("catch 블럭 수행");
             System.out.println(e.getMessage());
        }
        System.out.println("블록 이후의 문장이 수행되어집니다.");

    }
}

// 결과
try 블럭 수행
ArrayIndexOutOfBoundsException catch 블럭 수행하기
Index 8 out of bounds for length 5
블록 이후의 문장이 수행되어집니다.

```
여기서는 null exception이 발생하지 않고 ArrayIndexOutOfBoundsException 이 발생했기 때문에 해당 예외처리를 구현한 catch 블럭에서 잡혔습니다.

그런데 코드의 양이 많아지고, 예외처리를 해야될게 증가하게 되면 이를 놓치는 문제가 발생할 수도 있습니다.
이를 어떻게 해결할 수있을까요?

모든 예외의 부모 클래스는 java.lang.Exception 입니다.

```
public class MutiCatch3 {

    public static void main(String[] args) {
        MutiCatch sample = new MutiCatch();
        sample.finallySample();
    }

    private void finallySample() {

        int[] intArr = null;
        try {
            intArr = new int[5];
            System.out.println("try 블럭 수행");
            System.out.println(intArr[8]);
        } catch (Exception e) { // Exception이 모든 예외클래스를 처리한다.
            System.out.println("catch 블럭 수행");
             System.out.println(e.getMessage());
        }catch (NullPointerException ex2){
            System.out.println("NullPointerException catch 블럭 수행하기");
            ex2.getMessage();
        } catch (ArrayIndexOutOfBoundsException ex) {
            System.out.println("ArrayIndexOutOfBoundsException catch 블럭 수행하기");
            System.out.println(ex.getMessage());
        }
        System.out.println("블록 이후의 문장이 수행되어집니다.");

    }
}
```
위의 코드에서 확인할 수있듯이 Except은 모든 예외를 받을 수 있습니다 그렇기에 예상치 못한 상황에 대비하여 
가장 마지막에 exception catch 블럭을 두어서 안전하게 예외처리를 진행할 수 있습니다.




